Workbook

Sheet Sheet1
A1: Manufacturer | B1: Model | C1: Year | D1: Weight | E1: Top Speed | F1: Range | G1: Acceleration | H1: Efficiency | I1: Price | J1: Country | K1: Region
A2: Polestar | B2: 2 | C2: =_xlfn.XLOOKUP($B2,Sheet2!$B:$B,Sheet2!$C:$C) -> 2020 | D2: 2113 | E2: 210 | F2: 400 | G2: 4.7 | H2: 181 | I2: 56440 | J2: Sweden | K2: Europe
A3: DS | B3: 3 Crossback E-Tense | C3: =_xlfn.XLOOKUP($B3,Sheet2!$B:$B,Sheet2!$C:$C) -> 2019 | D3: 1523 | E3: 150 | F3: 250 | G3: 8.7 | H3: 180 | I3: 37422 | J3: France | K3: Europe
A4: Polestar | B4: 4 | C4: 2023 | D4: 2300 | E4: 200 | F4: 600 | G4: 4.7 | H4: 170 | I4: 60000 | J4: Sweden | K4: Europe
A5: Fiat | B5: 500e Convertible | C5: =_xlfn.XLOOKUP($B5,Sheet2!$B:$B,Sheet2!$C:$C) -> 2020 | D5: 1330 | E5: 150 | F5: 250 | G5: 9 | H5: 168 | I5: 37900 | J5: Italy | K5: Europe
A6: Fiat | B6: 500e Hatchback | C6: =_xlfn.XLOOKUP($B6,Sheet2!$B:$B,Sheet2!$C:$C) -> 2020 | D6: 1330 | E6: 150 | F6: 250 | G6: 9 | H6: 168 | I6: 34900 | J6: Italy | K6: Europe
A7: Lucid | B7: Air | C7: =_xlfn.XLOOKUP($B7,Sheet2!$B:$B,Sheet2!$C:$C) -> 2021 | D7: 2374 | E7: 250 | F7: 610 | G7: 2.8 | H7: 180 | I7: 105000 | J7: USA | K7: America
A8: Opel | B8: Ampera-e | C8: =_xlfn.XLOOKUP($B8,Sheet2!$B:$B,Sheet2!$C:$C) -> 2017 | D8: 1616 | E8: 150 | F8: 335 | G8: 7.3 | H8: 173 | I8: 41906 | J8: Germany | K8: Europe
A9: Nissan | B9: Ariya 63kWh | C9: =_xlfn.XLOOKUP($B9,Sheet2!$B:$B,Sheet2!$C:$C) -> 2021 | D9: 2030 | E9: 160 | F9: 330 | G9: 7.5 | H9: 191 | I9: 45000 | J9: Japan | K9: Asia
A10: Nissan | B10: Ariya 87kWh | C10: =_xlfn.XLOOKUP($B10,Sheet2!$B:$B,Sheet2!$C:$C) -> 2021 | D10: 2121 | E10: 160 | F10: 440 | G10: 7.6 | H10: 198 | I10: 50000 | J10: Japan | K10: Asia
A11: Nissan | B11: Ariya e-4ORCE 63kWh | C11: =_xlfn.XLOOKUP($B11,Sheet2!$B:$B,Sheet2!$C:$C) -> 2021 | D11: 2135 | E11: 200 | F11: 325 | G11: 5.9 | H11: 194 | I11: 50000 | J11: Japan | K11: Asia
A12: Nissan | B12: Ariya e-4ORCE 87kWh | C12: =_xlfn.XLOOKUP($B12,Sheet2!$B:$B,Sheet2!$C:$C) -> 2021 | D12: 2275 | E12: 200 | F12: 420 | G12: 5.7 | H12: 207 | I12: 57500 | J12: Japan | K12: Asia
A13: Nissan | B13: Ariya e-4ORCE 87kWh Performance | C13: =_xlfn.XLOOKUP($B13,Sheet2!$B:$B,Sheet2!$C:$C) -> 2021 | D13: 2275 | E13: 200 | F13: 375 | G13: 5.1 | H13: 232 | I13: 65000 | J13: Japan | K13: Asia
A14: Jeep | B14: Avenger | C14: 2023 | D14: 1500 | E14: 150 | F14: 400 | G14: 9 | H14: 156 | I14: 40000 | J14: USA | K14: America
A15: Chevrolet | B15: Blazer EV | C15: 2023 | D15: 2160 | E15: 190 | F15: 515 | G15: 4 | H15: 200 | I15: 52000 | J15: USA | K15: America
A16: Toyota | B16: bZ4X | C16: 2022 | D16: 1950 | E16: 160 | F16: 500 | G16: 7.7 | H16: 166 | I16: 44000 | J16: Japan | K16: Asia
A17: Skoda | B17: CITIGOe iV | C17: =_xlfn.XLOOKUP($B17,Sheet2!$B:$B,Sheet2!$C:$C) -> 2019 | D17: 1235 | E17: 130 | F17: 195 | G17: 12.3 | H17: 166 | I17: 24534 | J17: Czechia | K17: Europe
A18: Mini | B18: Cooper SE | C18: =_xlfn.XLOOKUP($B18,Sheet2!$B:$B,Sheet2!$C:$C) -> 2020 | D18: 1365 | E18: 150 | F18: 185 | G18: 7.3 | H18: 156 | I18: 31681 | J18: UK | K18: Europe
A19: Opel | B19: Corsa-e | C19: =_xlfn.XLOOKUP($B19,Sheet2!$B:$B,Sheet2!$C:$C) -> 2019 | D19: 1455 | E19: 150 | F19: 275 | G19: 8.1 | H19: 164 | I19: 29146 | J19: Germany | K19: Europe
A20: Tesla | B20: Cybertruck Dual Motor | C20: =_xlfn.XLOOKUP($B20,Sheet2!$B:$B,Sheet2!$C:$C) -> 2024 | D20: 3000 | E20: 190 | F20: 460 | G20: 5 | H20: 261 | I20: 55000 | J20: USA | K20: America
A21: Tesla | B21: Cybertruck Single Motor | C21: =_xlfn.XLOOKUP($B21,Sheet2!$B:$B,Sheet2!$C:$C) -> 2024 | D21: 3000 | E21: 180 | F21: 390 | G21: 7 | H21: 256 | I21: 45000 | J21: USA | K21: America
A22: Tesla | B22: Cybertruck Tri Motor | C22: 2024 | D22: 3000 | E22: 210 | F22: 750 | G22: 3 | H22: 267 | I22: 75000 | J22: USA | K22: America
A23: Honda | B23: e | C23: =_xlfn.XLOOKUP($B23,Sheet2!$B:$B,Sheet2!$C:$C) -> 2020 | D23: 1514 | E23: 145 | F23: 170 | G23: 9.5 | H23: 168 | I23: 32997 | J23: Japan | K23: Asia
A24: Honda | B24: e Advance | C24: =_xlfn.XLOOKUP($B24,Sheet2!$B:$B,Sheet2!$C:$C) -> 2020 | D24: 1543 | E24: 145 | F24: 170 | G24: 8.3 | H24: 168 | I24: 35921 | J24: Japan | K24: Asia
A25: Peugeot | B25: e-2008 SUV | C25: =_xlfn.XLOOKUP($B25,Sheet2!$B:$B,Sheet2!$C:$C) -> 2020 | D25: 1548 | E25: 150 | F25: 250 | G25: 8.5 | H25: 180 | I25: 34361 | J25: France | K25: Europe
A26: Peugeot | B26: e-208 | C26: =_xlfn.XLOOKUP($B26,Sheet2!$B:$B,Sheet2!$C:$C) -> 2019 | D26: 1455 | E26: 150 | F26: 275 | G26: 8.1 | H26: 164 | I26: 29682 | J26: France | K26: Europe
A27: Citroen | B27: e-C4 | C27: =_xlfn.XLOOKUP($B27,Sheet2!$B:$B,Sheet2!$C:$C) -> 2020 | D27: 1541 | E27: 150 | F27: 250 | G27: 9.7 | H27: 180 | I27: 40000 | J27: France | K27: Europe
A28: Volkswagen | B28: e-Golf | C28: =_xlfn.XLOOKUP($B28,Sheet2!$B:$B,Sheet2!$C:$C) -> 2014 | D28: 1585 | E28: 150 | F28: 190 | G28: 9.6 | H28: 168 | I28: 31900 | J28: Germany | K28: Europe
A29: Kia | B29: e-Niro 39 kWh | C29: =_xlfn.XLOOKUP($B29,Sheet2!$B:$B,Sheet2!$C:$C) -> 2018 | D29: 1750 | E29: 155 | F29: 235 | G29: 9.8 | H29: 167 | I29: 34400 | J29: South Korea | K29: Asia
A30: Kia | B30: e-Niro 64 kWh | C30: =_xlfn.XLOOKUP($B30,Sheet2!$B:$B,Sheet2!$C:$C) -> 2018 | D30: 1812 | E30: 167 | F30: 370 | G30: 7.8 | H30: 173 | I30: 38105 | J30: South Korea | K30: Asia
A31: Nissan | B31: e-NV200 Evalia | C31: =_xlfn.XLOOKUP($B31,Sheet2!$B:$B,Sheet2!$C:$C) -> 2014 | D31: 1551 | E31: 123 | F31: 190 | G31: 14 | H31: 200 | I31: 33246 | J31: Japan | K31: Asia
A32: Kia | B32: e-Soul 39 kWh | C32: =_xlfn.XLOOKUP($B32,Sheet2!$B:$B,Sheet2!$C:$C) -> 2019 | D32: 1723 | E32: 157 | F32: 230 | G32: 9.9 | H32: 170 | I32: 33133 | J32: South Korea | K32: Asia
A33: Kia | B33: e-Soul 64 kWh | C33: =_xlfn.XLOOKUP($B33,Sheet2!$B:$B,Sheet2!$C:$C) -> 2019 | D33: 1757 | E33: 167 | F33: 365 | G33: 7.9 | H33: 175 | I33: 36837 | J33: South Korea | K33: Asia
A34: Audi | B34: e-tron 50 quattro | C34: =_xlfn.XLOOKUP($B34,Sheet2!$B:$B,Sheet2!$C:$C) -> 2019 | D34: 2565 | E34: 190 | F34: 280 | G34: 6.8 | H34: 231 | I34: 67358 | J34: Germany | K34: Europe
... A51: Mercedes | B51: EQA | C51: =_xlfn.XLOOKUP($B51,Sheet2!$B:$B,Sheet2!$C:$C) -> 2021 | D51: 2040 | E51: 200 | F51: 350 | G51: 5 | H51: 171 | I51: 45000 | J51: Germany | K51: Europe
A52: Mercedes-Benz | B52: EQB | C52: 2022 | D52: 2160 | E52: 160 | F52: 423 | G52: 6.2 | H52: 200 | I52: 55000 | J52: Germany | K52: Europe
A53: Mercedes | B53: EQC 400 4MATIC | C53: =_xlfn.XLOOKUP($B53,Sheet2!$B:$B,Sheet2!$C:$C) -> 2019 | D53: 2495 | E53: 180 | F53: 370 | G53: 5.1 | H53: 216 | I53: 69484 | J53: Germany | K53: Europe
A54: Mercedes | B54: EQE SUV | C54: 2023 | D54: 2605 | E54: 210 | F54: 560 | G54: 4.9 | H54: 180 | I54: 76000 | J54: Germany | K54: Europe
A55: Mercedes | B55: EQV 300 Long | C55: =_xlfn.XLOOKUP($B55,Sheet2!$B:$B,Sheet2!$C:$C) -> 2020 | D55: 3170 | E55: 140 | F55: 330 | G55: 10 | H55: 273 | I55: 70631 | J55: Germany | K55: Europe
A56: Kia | B56: EV9 | C56: 2023 | D56: 2500 | E56: 185 | F56: 500 | G56: 5.2 | H56: 200 | I56: 70000 | J56: South Korea | K56: Asia
...

Sheet Sheet2
A1: Tesla | B1: Model 3 Long Range Dual Motor | C1: 2018
A2: Volkswagen | B2: ID.3 Pure | C2: 2020
A3: Polestar | B3: 2 | C3: 2020
A4: BMW | B4: iX3 | C4: 2020
A5: Honda | B5: e | C5: 2020
A6: Lucid | B6: Air | C6: 2021
A7: Volkswagen | B7: e-Golf | C7: 2014
A8: Peugeot | B8: e-208 | C8: 2019
A9: Tesla | B9: Model 3 Standard Range Plus | C9: 2019
A10: Audi | B10: Q4 e-tron | C10: 2021
A11: Mercedes | B11: EQC 400 4MATIC | C11: 2019
A12: Nissan | B12: Leaf | C12: 2010
A13: Hyundai | B13: Kona Electric 64 kWh | C13: 2018
A14: BMW | B14: i4 | C14: 2021
A15: Hyundai | B15: IONIQ Electric | C15: 2016
... A33: Renault | B33: Zoe ZE50 R110 | C33: 2019
A34: Tesla | B34: Cybertruck Tri Motor | C34: Expected in 2024
A35: Mazda | B35: MX-30 | C35: 2020
A36: Nissan | B36: Leaf e+ | C36: 2019
A37: Lexus | B37: UX 300e | C37: 2020
A38: CUPRA | B38: el-Born | C38: 2021
A39: Renault | B39: Zoe ZE50 R135 | C39: 2019
A40: Mercedes | B40: EQA | C40: 2021
A41: Tesla | B41: Model S Long Range | C41: 2021
A42: Hyundai | B42: Kona Electric 39 kWh | C42: 2018
A43: Audi | B43: e-tron Sportback 55 quattro | C43: 2020
A44: Skoda | B44: CITIGOe iV | C44: 2019
A45: SEAT | B45: Mii Electric | C45: 2019
A46: Kia | B46: e-Soul 64 kWh | C46: 2019
... A48: Porsche | B48: Taycan 4S | C48: 2019
A49: Lightyear | B49: One | C49: Expected in 2024
A50: Aiways | B50: U5 | C50: 2020
A51: Audi | B51: e-tron 55 quattro | C51: 2019
A52: Tesla | B52: Roadster | C52: Expected in 2024
A53: Opel | B53: Mokka-e | C53: 2020
A54: Skoda | B54: Enyaq iV 80 | C54: 2020
A55: Tesla | B55: Model X Long Range | C55: 2016
A56: Honda | B56: e Advance | C56: 2020
A57: DS | B57: 3 Crossback E-Tense | C57: 2019
A58: Renault | B58: Twingo ZE | C58: 2020
...
